Traceback (most recent call last):
  File "create_dataset.py", line 22, in <module>
    return_code = main()
  File "create_dataset.py", line 18, in main
    dataset.create_dataset()
  File "/home/bletchkey/ASGNTC/src/gol_adv_sys/DatasetManager.py", line 182, in create_dataset
    data = torch.stack(shuffled_configs, dim=0)
torch.cuda.OutOfMemoryError: CUDA out of memory. Tried to allocate 6.01 GiB. GPU 0 has a total capacty of 23.67 GiB of which 3.79 GiB is free. Including non-PyTorch memory, this process has 19.80 GiB memory in use. Of the allocated memory 18.08 GiB is allocated by PyTorch, and 1.48 GiB is reserved by PyTorch but unallocated. If reserved but unallocated memory is large try setting max_split_size_mb to avoid fragmentation.  See documentation for Memory Management and PYTORCH_CUDA_ALLOC_CONF
Traceback (most recent call last):
  File "plot_dataset_info.py", line 178, in <module>
    return_code = main()
  File "plot_dataset_info.py", line 173, in main
    check_dataset_configs(saving_path, dataset, metadata)
  File "plot_dataset_info.py", line 118, in check_dataset_configs
    ax.imshow(config[img_idx].cpu(), cmap='gray')
  File "/home/bletchkey/.local/lib/python3.8/site-packages/matplotlib/__init__.py", line 1446, in inner
    return func(ax, *map(sanitize_sequence, args), **kwargs)
  File "/home/bletchkey/.local/lib/python3.8/site-packages/matplotlib/axes/_axes.py", line 5663, in imshow
    im.set_data(X)
  File "/home/bletchkey/.local/lib/python3.8/site-packages/matplotlib/image.py", line 710, in set_data
    raise TypeError("Invalid shape {} for image data"
TypeError: Invalid shape (1, 32, 32) for image data
Traceback (most recent call last):
  File "plot_dataset_info.py", line 177, in <module>
    return_code = main()
  File "plot_dataset_info.py", line 172, in main
    check_dataset_configs(saving_path, dataset, metadata)
  File "plot_dataset_info.py", line 115, in check_dataset_configs
    ax = axs[config_idx, img_idx]
IndexError: index 10 is out of bounds for axis 0 with size 10
plot_dataset_info.py:126: UserWarning: Tight layout not applied. tight_layout cannot make axes width small enough to accommodate all axes decorations
  plt.tight_layout()
Traceback (most recent call last):
  File "plot_dataset_info.py", line 222, in <module>
    return_code = main()
  File "plot_dataset_info.py", line 218, in main
    check_transient_phases(saving_path, metadata)
  File "plot_dataset_info.py", line 189, in check_transient_phases
    plt.bar(ids, transient_phases, color='blue')
  File "/home/bletchkey/.local/lib/python3.8/site-packages/matplotlib/pyplot.py", line 2439, in bar
    return gca().bar(
  File "/home/bletchkey/.local/lib/python3.8/site-packages/matplotlib/__init__.py", line 1446, in inner
    return func(ax, *map(sanitize_sequence, args), **kwargs)
  File "/home/bletchkey/.local/lib/python3.8/site-packages/matplotlib/axes/_axes.py", line 2486, in bar
    self.add_patch(r)
  File "/home/bletchkey/.local/lib/python3.8/site-packages/matplotlib/axes/_base.py", line 2379, in add_patch
    self._update_patch_limits(p)
  File "/home/bletchkey/.local/lib/python3.8/site-packages/matplotlib/axes/_base.py", line 2405, in _update_patch_limits
    vertices.append(curve([0, *dzeros, 1]))
KeyboardInterrupt
Traceback (most recent call last):
  File "plot_dataset_info.py", line 222, in <module>
    return_code = main()
  File "plot_dataset_info.py", line 217, in main
    check_dataset_configs(saving_path, dataset, metadata)
  File "plot_dataset_info.py", line 172, in check_dataset_configs
    plt.savefig(Path(saving_path) / f"configs_{png_idx+1}.png", bbox_inches='tight')
  File "/home/bletchkey/.local/lib/python3.8/site-packages/matplotlib/pyplot.py", line 1023, in savefig
    res = fig.savefig(*args, **kwargs)
  File "/home/bletchkey/.local/lib/python3.8/site-packages/matplotlib/figure.py", line 3378, in savefig
    self.canvas.print_figure(fname, **kwargs)
  File "/home/bletchkey/.local/lib/python3.8/site-packages/matplotlib/backend_bases.py", line 2366, in print_figure
    result = print_method(
  File "/home/bletchkey/.local/lib/python3.8/site-packages/matplotlib/backend_bases.py", line 2232, in <lambda>
    print_method = functools.wraps(meth)(lambda *args, **kwargs: meth(
  File "/home/bletchkey/.local/lib/python3.8/site-packages/matplotlib/backends/backend_agg.py", line 509, in print_png
    self._print_pil(filename_or_obj, "png", pil_kwargs, metadata)
  File "/home/bletchkey/.local/lib/python3.8/site-packages/matplotlib/backends/backend_agg.py", line 458, in _print_pil
    mpl.image.imsave(
  File "/home/bletchkey/.local/lib/python3.8/site-packages/matplotlib/image.py", line 1689, in imsave
    image.save(fname, **pil_kwargs)
  File "/usr/lib/python3/dist-packages/PIL/Image.py", line 2099, in save
    fp = builtins.open(filename, "w+b")
FileNotFoundError: [Errno 2] No such file or directory: '/media/yui/bletchkey/ASGNTC/data/plots/test/configs_8.png'
Traceback (most recent call last):
  File "plot_dataset_info.py", line 216, in <module>
    
  File "plot_dataset_info.py", line 209, in main
    
  File "plot_dataset_info.py", line 112, in check_transient_phases
    
  File "/home/bletchkey/.local/lib/python3.8/site-packages/matplotlib/pyplot.py", line 2439, in bar
    return gca().bar(
  File "/home/bletchkey/.local/lib/python3.8/site-packages/matplotlib/__init__.py", line 1446, in inner
    return func(ax, *map(sanitize_sequence, args), **kwargs)
  File "/home/bletchkey/.local/lib/python3.8/site-packages/matplotlib/axes/_axes.py", line 2486, in bar
    self.add_patch(r)
  File "/home/bletchkey/.local/lib/python3.8/site-packages/matplotlib/axes/_base.py", line 2378, in add_patch
    p.set_clip_path(self.patch)
  File "/home/bletchkey/.local/lib/python3.8/site-packages/matplotlib/artist.py", line 809, in set_clip_path
    path.get_transform())
  File "/home/bletchkey/.local/lib/python3.8/site-packages/matplotlib/patches.py", line 264, in get_transform
    return self.get_patch_transform() + artist.Artist.get_transform(self)
  File "/home/bletchkey/.local/lib/python3.8/site-packages/matplotlib/patches.py", line 755, in get_patch_transform
    return transforms.BboxTransformTo(bbox) \
  File "/home/bletchkey/.local/lib/python3.8/site-packages/matplotlib/transforms.py", line 1350, in __add__
    return (composite_transform_factory(self, other)
  File "/home/bletchkey/.local/lib/python3.8/site-packages/matplotlib/transforms.py", line 2535, in composite_transform_factory
    return CompositeGenericTransform(a, b)
  File "/home/bletchkey/.local/lib/python3.8/site-packages/matplotlib/transforms.py", line 2373, in __init__
    self.set_children(a, b)
  File "/home/bletchkey/.local/lib/python3.8/site-packages/matplotlib/transforms.py", line 204, in set_children
    for child in children:
KeyboardInterrupt
Traceback (most recent call last):
  File "plot_dataset_info.py", line 218, in <module>
    return_code = main()
  File "plot_dataset_info.py", line 214, in main
    check_transient_phases_qq(saving_path, metadata)
  File "plot_dataset_info.py", line 172, in check_transient_phases_qq
    stats.probplot(transient_phases, dist="norm", plot=axs[1])
NameError: name 'stats' is not defined
Traceback (most recent call last):
  File "plot_dataset_info.py", line 229, in <module>
    return_code = main()
  File "plot_dataset_info.py", line 222, in main
    check_dataset_configs(saving_path, dataset, metadata)
  File "plot_dataset_info.py", line 82, in check_dataset_configs
    ax = fig.add_subplot(gs[config_idx, i])
  File "/home/bletchkey/.local/lib/python3.8/site-packages/matplotlib/gridspec.py", line 258, in __getitem__
    [_normalize(k1, nrows, 0), _normalize(k2, ncols, 1)],
  File "/home/bletchkey/.local/lib/python3.8/site-packages/matplotlib/gridspec.py", line 246, in _normalize
    raise IndexError(f"index {orig_key} is out of bounds for "
IndexError: index 6 is out of bounds for axis 1 with size 6
Traceback (most recent call last):
  File "plot_dataset_info.py", line 229, in <module>
    return_code = main()
  File "plot_dataset_info.py", line 222, in main
    check_dataset_configs(saving_path, dataset, metadata)
  File "plot_dataset_info.py", line 82, in check_dataset_configs
    ax = fig.add_subplot(gs[config_idx, i])
  File "/home/bletchkey/.local/lib/python3.8/site-packages/matplotlib/gridspec.py", line 258, in __getitem__
    [_normalize(k1, nrows, 0), _normalize(k2, ncols, 1)],
  File "/home/bletchkey/.local/lib/python3.8/site-packages/matplotlib/gridspec.py", line 246, in _normalize
    raise IndexError(f"index {orig_key} is out of bounds for "
IndexError: index 6 is out of bounds for axis 1 with size 6
Traceback (most recent call last):
  File "plot_dataset_info.py", line 215, in <module>
    return_code = main()
  File "plot_dataset_info.py", line 208, in main
    check_dataset_configs(saving_path, dataset, metadata)
  File "plot_dataset_info.py", line 87, in check_dataset_configs
    ax = fig.add_subplot(gs[j, id])
  File "/home/bletchkey/.local/lib/python3.8/site-packages/matplotlib/gridspec.py", line 258, in __getitem__
    [_normalize(k1, nrows, 0), _normalize(k2, ncols, 1)],
  File "/home/bletchkey/.local/lib/python3.8/site-packages/matplotlib/gridspec.py", line 246, in _normalize
    raise IndexError(f"index {orig_key} is out of bounds for "
IndexError: index 20 is out of bounds for axis 0 with size 20
Traceback (most recent call last):
  File "plot_dataset_info.py", line 216, in <module>
    if __name__ == "__main__":
  File "plot_dataset_info.py", line 209, in main
    
  File "plot_dataset_info.py", line 88, in check_dataset_configs
    ax.set_title(titles[id], loc='center', fontsize=20, pad=20)
  File "/home/bletchkey/.local/lib/python3.8/site-packages/matplotlib/gridspec.py", line 258, in __getitem__
    [_normalize(k1, nrows, 0), _normalize(k2, ncols, 1)],
  File "/home/bletchkey/.local/lib/python3.8/site-packages/matplotlib/gridspec.py", line 246, in _normalize
    raise IndexError(f"index {orig_key} is out of bounds for "
IndexError: index 20 is out of bounds for axis 0 with size 20
Traceback (most recent call last):
  File "plot_dataset_info.py", line 217, in <module>
    return_code = main()
  File "plot_dataset_info.py", line 210, in main
    check_dataset_configs(saving_path, dataset, metadata)
  File "plot_dataset_info.py", line 89, in check_dataset_configs
    ax = fig.add_subplot(gs[j, id])
  File "/home/bletchkey/.local/lib/python3.8/site-packages/matplotlib/gridspec.py", line 258, in __getitem__
    [_normalize(k1, nrows, 0), _normalize(k2, ncols, 1)],
  File "/home/bletchkey/.local/lib/python3.8/site-packages/matplotlib/gridspec.py", line 246, in _normalize
    raise IndexError(f"index {orig_key} is out of bounds for "
IndexError: index 20 is out of bounds for axis 0 with size 20
Traceback (most recent call last):
  File "plot_dataset_info.py", line 217, in <module>
    return_code = main()
  File "plot_dataset_info.py", line 210, in main
    check_dataset_configs(saving_path, dataset, metadata)
  File "plot_dataset_info.py", line 63, in check_dataset_configs
    gs = GridSpec(img_text_rows, 6, figure=fig, height_ratios=[6] + [1]*19, hspace=0.1, wspace=0.1)
  File "/home/bletchkey/.local/lib/python3.8/site-packages/matplotlib/gridspec.py", line 379, in __init__
    super().__init__(nrows, ncols,
  File "/home/bletchkey/.local/lib/python3.8/site-packages/matplotlib/gridspec.py", line 55, in __init__
    self.set_height_ratios(height_ratios)
  File "/home/bletchkey/.local/lib/python3.8/site-packages/matplotlib/gridspec.py", line 133, in set_height_ratios
    raise ValueError('Expected the given number of height ratios to '
ValueError: Expected the given number of height ratios to match the number of rows of the grid
Traceback (most recent call last):
  File "plot_dataset_info.py", line 8, in <module>
    from scipy import stats
ModuleNotFoundError: No module named 'scipy'
Traceback (most recent call last):
  File "plot_dataset_info.py", line 183, in <module>
    if __name__ == "__main__":
  File "plot_dataset_info.py", line 176, in main
    
  File "plot_dataset_info.py", line 76, in check_dataset_configs
    image_ax.axis('off').set_title(titles[col], loc='center', fontsize=20, pad=20)
AttributeError: 'tuple' object has no attribute 'set_title'
Traceback (most recent call last):
  File "plot_dataset_info.py", line 186, in <module>
    return_code = main()
  File "plot_dataset_info.py", line 179, in main
    check_dataset_configs(saving_path, dataset, metadata)
  File "plot_dataset_info.py", line 55, in check_dataset_configs
    plt.subplots_adjust(left=0.05, right=0.95, top=0, bottom=0.1, wspace=0.1, hspace=0.4)
  File "/home/bletchkey/.local/lib/python3.8/site-packages/matplotlib/pyplot.py", line 2335, in subplots_adjust
    return gcf().subplots_adjust(
  File "/home/bletchkey/.local/lib/python3.8/site-packages/matplotlib/figure.py", line 1353, in subplots_adjust
    self.subplotpars.update(left, bottom, right, top, wspace, hspace)
  File "/home/bletchkey/.local/lib/python3.8/site-packages/matplotlib/figure.py", line 166, in update
    raise ValueError('bottom cannot be >= top')
ValueError: bottom cannot be >= top
Traceback (most recent call last):
  File "plot_dataset_info.py", line 148, in <module>
    return_code = main()
  File "plot_dataset_info.py", line 139, in main
    dataset = torch.load(ds_path)
  File "/home/bletchkey/.local/lib/python3.8/site-packages/torch/serialization.py", line 1014, in load
    return _load(opened_zipfile,
  File "/home/bletchkey/.local/lib/python3.8/site-packages/torch/serialization.py", line 1422, in _load
    result = unpickler.load()
  File "/home/bletchkey/.local/lib/python3.8/site-packages/torch/serialization.py", line 1392, in persistent_load
    typed_storage = load_tensor(dtype, nbytes, key, _maybe_decode_ascii(location))
  File "/home/bletchkey/.local/lib/python3.8/site-packages/torch/serialization.py", line 1366, in load_tensor
    wrap_storage=restore_location(storage, location),
  File "/home/bletchkey/.local/lib/python3.8/site-packages/torch/serialization.py", line 381, in default_restore_location
    result = fn(storage, location)
  File "/home/bletchkey/.local/lib/python3.8/site-packages/torch/serialization.py", line 279, in _cuda_deserialize
    return obj.cuda(device)
  File "/home/bletchkey/.local/lib/python3.8/site-packages/torch/_utils.py", line 114, in _cuda
    untyped_storage = torch.UntypedStorage(
torch.cuda.OutOfMemoryError: CUDA out of memory. Tried to allocate 6.01 GiB. GPU 0 has a total capacty of 23.67 GiB of which 5.17 GiB is free. Process 46473 has 12.21 GiB memory in use. Including non-PyTorch memory, this process has 6.20 GiB memory in use. Of the allocated memory 6.01 GiB is allocated by PyTorch, and 0 bytes is reserved by PyTorch but unallocated. If reserved but unallocated memory is large try setting max_split_size_mb to avoid fragmentation.  See documentation for Memory Management and PYTORCH_CUDA_ALLOC_CONF
